[INFO][0][<module>] Linux login3.cm.cluster 5.14.0-362.24.1.el9_3.x86_64 #1 SMP PREEMPT_DYNAMIC Thu Feb 15 07:18:13 EST 2024 x86_64 x86_64
[INFO][0][<module>] /home/renatob/miniconda3/envs/ilamb/lib/python3.11/site-packages/ILAMB (2.7)
[INFO][0][<module>] /home/renatob/miniconda3/envs/ilamb/lib/python3.11/site-packages/numpy (1.26.4)
[INFO][0][<module>] /home/renatob/miniconda3/envs/ilamb/lib/python3.11/site-packages/matplotlib (3.9.1)
[INFO][0][<module>] /home/renatob/miniconda3/envs/ilamb/lib/python3.11/site-packages/netCDF4 (1.7.1)
[INFO][0][<module>] /home/renatob/miniconda3/envs/ilamb/lib/python3.11/site-packages/cf_units (3.2.0)
[INFO][0][<module>] /home/renatob/miniconda3/envs/ilamb/lib/python3.11/site-packages/sympy (1.13.1)
[INFO][0][<module>] /home/renatob/miniconda3/envs/ilamb/lib/python3.11/site-packages/mpi4py (4.0.0)
[INFO][0][<module>] 2024-08-28 13:02:11.215544
[DEBUG][0][WorkConfront][GrossPrimaryProductivity/FLUXNET2015][CARDAMOM]
Traceback (most recent call last):
  File "/home/renatob/miniconda3/envs/ilamb/bin/ilamb-run", line 561, in WorkConfront
    c.confront(m)
  File "/home/renatob/miniconda3/envs/ilamb/lib/python3.11/site-packages/ILAMB/Confrontation.py", line 433, in confront
    obs, mod = self.stageData(m)
               ^^^^^^^^^^^^^^^^^
  File "/home/renatob/miniconda3/envs/ilamb/lib/python3.11/site-packages/ILAMB/Confrontation.py", line 371, in stageData
    mod = m.extractTimeSeries(
          ^^^^^^^^^^^^^^^^^^^^
  File "/home/renatob/miniconda3/envs/ilamb/lib/python3.11/site-packages/ILAMB/ModelResult.py", line 359, in extractTimeSeries
    var = Variable(
          ^^^^^^^^^
  File "/home/renatob/miniconda3/envs/ilamb/lib/python3.11/site-packages/ILAMB/Variable.py", line 140, in __init__
    out = il.FromNetCDF4(
          ^^^^^^^^^^^^^^^
  File "/home/renatob/miniconda3/envs/ilamb/lib/python3.11/site-packages/ILAMB/ilamblib.py", line 940, in FromNetCDF4
    t, t_bnd, cbounds, begin, end, calendar = GetTime(
                                              ^^^^^^^^
  File "/home/renatob/miniconda3/envs/ilamb/lib/python3.11/site-packages/ILAMB/ilamblib.py", line 393, in GetTime
    TB[index] = ConvertCalendar(
                ^^^^^^^^^^^^^^^^
  File "/home/renatob/miniconda3/envs/ilamb/lib/python3.11/site-packages/ILAMB/ilamblib.py", line 249, in ConvertCalendar
    return cf.date2num(
           ^^^^^^^^^^^^
  File "src/cftime/_cftime.pyx", line 288, in cftime._cftime.date2num
  File "src/cftime/_cftime.pyx", line 400, in cftime._cftime.to_calendar_specific_datetime
  File "src/cftime/_cftime.pyx", line 2084, in cftime._cftime.DatetimeNoLeap.__init__
  File "src/cftime/_cftime.pyx", line 1172, in cftime._cftime.datetime.__init__
  File "src/cftime/_cftime.pyx", line 1765, in cftime._cftime.assert_valid_date
ValueError: invalid day number provided in cftime.DatetimeNoLeap(2004, 2, 29, 0, 0, 0, 0, has_year_zero=True)

[DEBUG][0][extractTimeSeries][CLM40cn] Could not find [gpp] in the model results
[DEBUG][0][WorkConfront][GrossPrimaryProductivity/FLUXNET2015][CLM40cn]
Traceback (most recent call last):
  File "/home/renatob/miniconda3/envs/ilamb/bin/ilamb-run", line 561, in WorkConfront
    c.confront(m)
  File "/home/renatob/miniconda3/envs/ilamb/lib/python3.11/site-packages/ILAMB/Confrontation.py", line 433, in confront
    obs, mod = self.stageData(m)
               ^^^^^^^^^^^^^^^^^
  File "/home/renatob/miniconda3/envs/ilamb/lib/python3.11/site-packages/ILAMB/Confrontation.py", line 371, in stageData
    mod = m.extractTimeSeries(
          ^^^^^^^^^^^^^^^^^^^^
  File "/home/renatob/miniconda3/envs/ilamb/lib/python3.11/site-packages/ILAMB/ModelResult.py", line 433, in extractTimeSeries
    raise il.VarNotInModel()
ILAMB.ilamblib.VarNotInModel: VarNotInModel

[DEBUG][0][WorkConfront][GrossPrimaryProductivity/FLUXCOM][CARDAMOM]
Traceback (most recent call last):
  File "/home/renatob/miniconda3/envs/ilamb/bin/ilamb-run", line 561, in WorkConfront
    c.confront(m)
  File "/home/renatob/miniconda3/envs/ilamb/lib/python3.11/site-packages/ILAMB/Confrontation.py", line 433, in confront
    obs, mod = self.stageData(m)
               ^^^^^^^^^^^^^^^^^
  File "/home/renatob/miniconda3/envs/ilamb/lib/python3.11/site-packages/ILAMB/Confrontation.py", line 371, in stageData
    mod = m.extractTimeSeries(
          ^^^^^^^^^^^^^^^^^^^^
  File "/home/renatob/miniconda3/envs/ilamb/lib/python3.11/site-packages/ILAMB/ModelResult.py", line 359, in extractTimeSeries
    var = Variable(
          ^^^^^^^^^
  File "/home/renatob/miniconda3/envs/ilamb/lib/python3.11/site-packages/ILAMB/Variable.py", line 140, in __init__
    out = il.FromNetCDF4(
          ^^^^^^^^^^^^^^^
  File "/home/renatob/miniconda3/envs/ilamb/lib/python3.11/site-packages/ILAMB/ilamblib.py", line 940, in FromNetCDF4
    t, t_bnd, cbounds, begin, end, calendar = GetTime(
                                              ^^^^^^^^
  File "/home/renatob/miniconda3/envs/ilamb/lib/python3.11/site-packages/ILAMB/ilamblib.py", line 393, in GetTime
    TB[index] = ConvertCalendar(
                ^^^^^^^^^^^^^^^^
  File "/home/renatob/miniconda3/envs/ilamb/lib/python3.11/site-packages/ILAMB/ilamblib.py", line 249, in ConvertCalendar
    return cf.date2num(
           ^^^^^^^^^^^^
  File "src/cftime/_cftime.pyx", line 288, in cftime._cftime.date2num
  File "src/cftime/_cftime.pyx", line 400, in cftime._cftime.to_calendar_specific_datetime
  File "src/cftime/_cftime.pyx", line 2084, in cftime._cftime.DatetimeNoLeap.__init__
  File "src/cftime/_cftime.pyx", line 1172, in cftime._cftime.datetime.__init__
  File "src/cftime/_cftime.pyx", line 1765, in cftime._cftime.assert_valid_date
ValueError: invalid day number provided in cftime.DatetimeNoLeap(2004, 2, 29, 0, 0, 0, 0, has_year_zero=True)

[INFO][1][MakeComparable][GrossPrimaryProductivity/FLUXCOM][ENSEMBLE-CMIP6] Spatial data was clipped from the reference:  before: [408 360 720] after: [408 273 710]
[INFO][1][MakeComparable][GrossPrimaryProductivity/FLUXCOM][ENSEMBLE-CMIP6] Spatial data was clipped from the comparison:  before: [408  96 144] after: [408  73 142]
[DEBUG][0][extractTimeSeries][CLM40cn] Could not find [gpp] in the model results
[DEBUG][0][WorkConfront][GrossPrimaryProductivity/FLUXCOM][CLM40cn]
Traceback (most recent call last):
  File "/home/renatob/miniconda3/envs/ilamb/bin/ilamb-run", line 561, in WorkConfront
    c.confront(m)
  File "/home/renatob/miniconda3/envs/ilamb/lib/python3.11/site-packages/ILAMB/Confrontation.py", line 433, in confront
    obs, mod = self.stageData(m)
               ^^^^^^^^^^^^^^^^^
  File "/home/renatob/miniconda3/envs/ilamb/lib/python3.11/site-packages/ILAMB/Confrontation.py", line 371, in stageData
    mod = m.extractTimeSeries(
          ^^^^^^^^^^^^^^^^^^^^
  File "/home/renatob/miniconda3/envs/ilamb/lib/python3.11/site-packages/ILAMB/ModelResult.py", line 433, in extractTimeSeries
    raise il.VarNotInModel()
ILAMB.ilamblib.VarNotInModel: VarNotInModel

